try:
    pass
except Exception as exception:
    print(exception)
